<?xml version="1.0" encoding="utf-8"?>
<!-- This URDF was automatically created by SolidWorks to URDF Exporter! Originally created by Stephen Brawner (brawner@gmail.com) 
     Commit Version: 1.6.0-4-g7f85cfe  Build Version: 1.6.7995.38578
     For more information, please see http://wiki.ros.org/sw_urdf_exporter -->
<robot name="bfmc_car_description" xmlns:xacro="http://www.ros.org/wiki/xacro">
  <!-- DepthAI OAK-D Pro camera model and TF frames.
       The package depthai_descriptions is installed from ros-${ROS_DISTRO}-depthai-ros. -->
  <xacro:include filename="$(find depthai_descriptions)/urdf/include/depthai_macro.urdf.xacro"/>

  <link
    name="base_link">
    <inertial>
      <origin
        xyz="0.135 6.93889390390723E-17 -0.005"
        rpy="0 0 0" />
      <mass
        value="0.49" />
      <inertia
        ixx="0.000804416666666667"
        ixy="-9.62337848298127E-20"
        ixz="-1.10552481521105E-21"
        iyy="0.00500616666666666"
        iyz="-2.31413918698927E-21"
        izz="0.00580241666666666" />
    </inertial>
    <visual>
      <origin
        xyz="0 0 0"
        rpy="0 0 0" />
      <geometry>
        <mesh
          filename="package://bfmc_car_description/meshes/base_link.STL" />
      </geometry>
      <material
        name="">
        <color
          rgba="0.792156862745098 0.819607843137255 0.933333333333333 1" />
      </material>
    </visual>
    <collision>
      <origin
        xyz="0 0 0"
        rpy="0 0 0" />
      <geometry>
        <mesh
          filename="package://bfmc_car_description/meshes/base_link.STL" />
      </geometry>
    </collision>
  </link>
  <link
    name="camera_mount_link">
    <inertial>
      <origin
        xyz="-0.00942839248304894 0.0015349334670499 -0.0105958484470582"
        rpy="0 0 0" />
      <mass
        value="0.0317602721532027" />
      <inertia
        ixx="8.91808136721681E-06"
        ixy="1.27804504034124E-07"
        ixz="-2.38980667904457E-07"
        iyy="6.11981500646794E-06"
        iyz="8.1492724654572E-07"
        izz="1.02408078186826E-05" />
    </inertial>
    <visual>
      <origin
        xyz="0 0 0"
        rpy="0 0 0" />
      <geometry>
        <mesh
          filename="package://bfmc_car_description/meshes/camera_mount_link.STL" />
      </geometry>
      <material
        name="">
        <color
          rgba="0.792156862745098 0.819607843137255 0.933333333333333 1" />
      </material>
    </visual>
    <collision>
      <origin
        xyz="0 0 0"
        rpy="0 0 0" />
      <geometry>
        <mesh
          filename="package://bfmc_car_description/meshes/camera_mount_link.STL" />
      </geometry>
    </collision>
  </link>
  <joint
    name="base_to_camera_mount_joint"
    type="fixed">
    <origin
      xyz="0.18853 0.0025 0.097083"
      rpy="0 0.38397 0" />
    <parent
      link="base_link" />
    <child
      link="camera_mount_link" />
    <axis
      xyz="0 0 0" />
  </joint>
  <link
    name="camera_base_link">
    <inertial>
      <origin
        xyz="-0.0131960411571118 -0.000173082219518506 -0.00463193948361613"
        rpy="0 0 0" />
      <mass
        value="0.0206761114275171" />
      <inertia
        ixx="1.77975070392948E-05"
        ixy="-1.34409441413317E-08"
        ixz="-1.5980564905893E-08"
        iyy="2.05307099021103E-06"
        iyz="-8.59134890846374E-08"
        izz="1.6637825255002E-05" />
    </inertial>
    <!-- CAD camera visual removed: official OAK-D Pro visual comes from depthai_descriptions. -->
    <!-- CAD camera collision removed: official OAK-D Pro collision comes from depthai_descriptions. -->
  </link>
  <joint
    name="camera_mount_to_camera_base_joint"
    type="fixed">
    <origin
      xyz="0.029401 0 0.096464"
      rpy="0 0 0" />
    <parent
      link="camera_mount_link" />
    <child
      link="camera_base_link" />
    <axis
      xyz="0 0 0" />
  </joint>
  <link
    name="tyre_rear_left_link">
    <inertial>
      <origin
        xyz="-5.55111512312578E-17 0 -8.17378446053356E-20"
        rpy="0 0 0" />
      <mass
        value="0.0839234262255232" />
      <inertia
        ixx="2.60612835512728E-05"
        ixy="-5.72414267151622E-37"
        ixz="-1.68965426457498E-22"
        iyy="4.23000294247333E-05"
        iyz="-4.58049537032186E-38"
        izz="2.60612835512728E-05" />
    </inertial>
    <visual>
      <origin
        xyz="0 0 0"
        rpy="0 0 0" />
      <geometry>
        <mesh
          filename="package://bfmc_car_description/meshes/tyre_rear_left_link.STL" />
      </geometry>
      <material
        name="">
        <color
          rgba="0.792156862745098 0.819607843137255 0.933333333333333 1" />
      </material>
    </visual>
    <collision>
      <origin
        xyz="0 0 0"
        rpy="0 0 0" />
      <geometry>
        <mesh
          filename="package://bfmc_car_description/meshes/tyre_rear_left_link.STL" />
      </geometry>
    </collision>
  </link>
  <joint
    name="rear_left_wheel_joint"
    type="continuous">
    <origin
      xyz="0 0.085 -0.005"
      rpy="0 0 0" />
    <parent
      link="base_link" />
    <child
      link="tyre_rear_left_link" />
    <axis
      xyz="0 -1 0" />
  </joint>
  <link
    name="tyre_rear_right_link">
    <inertial>
      <origin
        xyz="-5.55111512312578E-17 1.73472347597681E-18 -6.18854024935433E-19"
        rpy="0 0 0" />
      <mass
        value="0.0839234262255231" />
      <inertia
        ixx="2.60612835512727E-05"
        ixy="-1.16752531275512E-25"
        ixz="-7.30676207755174E-25"
        iyy="4.23000294247332E-05"
        iyz="-7.47936882605865E-22"
        izz="2.60612835512727E-05" />
    </inertial>
    <visual>
      <origin
        xyz="0 0 0"
        rpy="0 0 0" />
      <geometry>
        <mesh
          filename="package://bfmc_car_description/meshes/tyre_rear_right_link.STL" />
      </geometry>
      <material
        name="">
        <color
          rgba="0.792156862745098 0.819607843137255 0.933333333333333 1" />
      </material>
    </visual>
    <collision>
      <origin
        xyz="0 0 0"
        rpy="0 0 0" />
      <geometry>
        <mesh
          filename="package://bfmc_car_description/meshes/tyre_rear_right_link.STL" />
      </geometry>
    </collision>
  </link>
  <joint
    name="rear_right_wheel_joint"
    type="continuous">
    <origin
      xyz="0 -0.085 -0.005"
      rpy="0 0 0" />
    <parent
      link="base_link" />
    <child
      link="tyre_rear_right_link" />
    <axis
      xyz="0 -1 0" />
  </joint>
  <link
    name="front_left_steering_link">
    <inertial>
      <origin
        xyz="-0.125 -0.07 -0.005"
        rpy="0 0 0" />
      <mass
        value="0.49" />
      <inertia
        ixx="0.000804416666666667"
        ixy="-9.62337848298127E-20"
        ixz="-1.10552481521105E-21"
        iyy="0.00500616666666666"
        iyz="-2.31413918698927E-21"
        izz="0.00580241666666666" />
    </inertial>
    <visual>
      <origin
        xyz="0 0 0"
        rpy="0 0 0" />
      <geometry>
        <mesh
          filename="package://bfmc_car_description/meshes/front_left_steering_link.STL" />
      </geometry>
      <material
        name="">
        <color
          rgba="0.792156862745098 0.819607843137255 0.933333333333333 1" />
      </material>
    </visual>
    <collision>
      <origin
        xyz="0 0 0"
        rpy="0 0 0" />
      <geometry>
        <mesh
          filename="package://bfmc_car_description/meshes/front_left_steering_link.STL" />
      </geometry>
    </collision>
  </link>
  <joint
    name="front_left_steering_joint"
    type="revolute">
    <origin
      xyz="0.26 0.07 0"
      rpy="0 0 0" />
    <parent
      link="base_link" />
    <child
      link="front_left_steering_link" />
    <axis
      xyz="0 0 1" />
    <limit
      lower="-0.6"
      upper="0.6"
      effort="1"
      velocity="1" />
  </joint>
  <link
    name="tyre_front_left_link">
    <inertial>
      <origin
        xyz="0 0 -3.84617040823464E-20"
        rpy="0 0 0" />
      <mass
        value="0.0839234262255232" />
      <inertia
        ixx="2.60612835512728E-05"
        ixy="7.48212436741299E-22"
        ixz="-3.94223250867939E-21"
        iyy="4.23000294247333E-05"
        iyz="-3.7410621837065E-22"
        izz="2.60612835512728E-05" />
    </inertial>
    <visual>
      <origin
        xyz="0 0 0"
        rpy="0 0 0" />
      <geometry>
        <mesh
          filename="package://bfmc_car_description/meshes/tyre_front_left_link.STL" />
      </geometry>
      <material
        name="">
        <color
          rgba="0.792156862745098 0.819607843137255 0.933333333333333 1" />
      </material>
    </visual>
    <collision>
      <origin
        xyz="0 0 0"
        rpy="0 0 0" />
      <geometry>
        <mesh
          filename="package://bfmc_car_description/meshes/tyre_front_left_link.STL" />
      </geometry>
    </collision>
  </link>
  <joint
    name="front_left_wheel_joint"
    type="continuous">
    <origin
      xyz="0 0.015 -0.005"
      rpy="0 0 0" />
    <parent
      link="front_left_steering_link" />
    <child
      link="tyre_front_left_link" />
    <axis
      xyz="0 -1 0" />
  </joint>
  <link
    name="front_right_steering_link">
    <inertial>
      <origin
        xyz="-0.125 0.07 -0.005"
        rpy="0 0 0" />
      <mass
        value="0.49" />
      <inertia
        ixx="0.000804416666666667"
        ixy="-9.62337848298127E-20"
        ixz="-1.10552481521105E-21"
        iyy="0.00500616666666666"
        iyz="-2.31413918698927E-21"
        izz="0.00580241666666666" />
    </inertial>
    <visual>
      <origin
        xyz="0 0 0"
        rpy="0 0 0" />
      <geometry>
        <mesh
          filename="package://bfmc_car_description/meshes/front_right_steering_link.STL" />
      </geometry>
      <material
        name="">
        <color
          rgba="0.792156862745098 0.819607843137255 0.933333333333333 1" />
      </material>
    </visual>
    <collision>
      <origin
        xyz="0 0 0"
        rpy="0 0 0" />
      <geometry>
        <mesh
          filename="package://bfmc_car_description/meshes/front_right_steering_link.STL" />
      </geometry>
    </collision>
  </link>
  <joint
    name="front_right_steering_joint"
    type="revolute">
    <origin
      xyz="0.26 -0.07 0"
      rpy="0 0 0" />
    <parent
      link="base_link" />
    <child
      link="front_right_steering_link" />
    <axis
      xyz="0 0 1" />
    <limit
      lower="-0.6"
      upper="0.6"
      effort="1"
      velocity="1" />
  </joint>
  <link
    name="tyre_front_right_link">
    <inertial>
      <origin
        xyz="-2.77555756156289E-17 3.46944695195361E-18 3.85900142922842E-21"
        rpy="0 0 0" />
      <mass
        value="0.0839234262255231" />
      <inertia
        ixx="2.60612835512727E-05"
        ixy="7.48212436741299E-22"
        ixz="9.35265545926623E-23"
        iyy="4.23000294247332E-05"
        iyz="-9.35265545926623E-23"
        izz="2.60612835512727E-05" />
    </inertial>
    <visual>
      <origin
        xyz="0 0 0"
        rpy="0 0 0" />
      <geometry>
        <mesh
          filename="package://bfmc_car_description/meshes/tyre_front_right_link.STL" />
      </geometry>
      <material
        name="">
        <color
          rgba="0.792156862745098 0.819607843137255 0.933333333333333 1" />
      </material>
    </visual>
    <collision>
      <origin
        xyz="0 0 0"
        rpy="0 0 0" />
      <geometry>
        <mesh
          filename="package://bfmc_car_description/meshes/tyre_front_right_link.STL" />
      </geometry>
    </collision>
  </link>
  <joint
    name="front_right_wheel_joint"
    type="continuous">
    <origin
      xyz="0 -0.015 -0.005"
      rpy="0 0 0" />
    <parent
      link="front_right_steering_link" />
    <child
      link="tyre_front_right_link" />
    <axis
      xyz="0 -1 0" />
  </joint>
  <link name="gps_tag_link"/>

  <joint name="base_link_to_gps_tag_joint" type="fixed">
    <parent link="base_link"/>
    <child link="gps_tag_link"/>
    <origin xyz="0.075 0 0.102" rpy="0 0 0"/>
  </joint>

  <!-- Rear IMU (BNO055) — position from SolidWorks assembly export -->
  <link name="imu_link"/>

  <joint name="base_link_to_imu_joint" type="fixed">
    <parent link="base_link"/>
    <child link="imu_link"/>
    <origin xyz="0.11 0 0.0145" rpy="0 0 0"/>
  </joint>

  <!-- Official OAK-D Pro description attached to the SolidWorks camera_base_link.
       If this duplicates the CAD camera visual, remove the visual/collision block of camera_base_link
       or remove this macro and keep only the CAD mesh. -->
  <xacro:depthai_camera
    camera_name="oak"
    camera_model="OAK-D-PRO"
    base_frame="oak-d-base_frame"
    parent="camera_base_link"
    cam_pos_x="0.0"
    cam_pos_y="0.0"
    cam_pos_z="0.0"
    cam_roll="0.0"
    cam_pitch="0.0"
    cam_yaw="0.0"/>

</robot>
